Workbook
Name Impact_list: [1]List!$C$34:$C$38
Name issues_list: [2]List!$C$49:$C$51
Name Prob_list: [1]List!$B$42:$B$46

Sheet Cover Page
A1: (RAID) log, RAID is a small tool that allows you to keep track of Risks, Assumptions/actions, issues, and Dependencies in your projects.
B3: Project Name: | C3: Nazeel Platform Modernization
B4: Project Number: | C4: SAMIEC003001
B5: RAID version: | C5: V0.1
B6: Last updated date: | C6: =TODAY() -> 46137
B7: Schedule (Latest Baseline) | C7: 46023
B8: Updated by: | C8: Tawah Alsindi
B10: Project Summary Statistics
B12: Total Actions/Assumptions: | C12: =COUNTA('Assumptions-Actions'!A:A)-1 -> 59 | E12: Total Risks: | F12: =COUNTIF(Risks!A:A,"R-*") -> 37 | H12: Total Issues: | I12: =COUNTIF(Issues!A:A,"I-*") -> 27 | K12: Total Dependencies: | L12: =COUNTA(Dependencies!A:A)-1 -> 25
B13: Completed: | C13: =COUNTIF('Assumptions-Actions'!G:G,"Completed") -> 32 | E13: Active Risks: | F13: =COUNTIF(Risks!F:F,"Active") -> 2 | H13: Active Issues: | I13: =COUNTIF(Issues!D:D,"Active") -> 2 | K13: Closed: | L13: =COUNTIF(Dependencies!G:G,"Closed") -> 12
B14: Delayed: | C14: =COUNTIF('Assumptions-Actions'!G:G,"Delayed") -> 8 | E14: Inactive Risks: | F14: =COUNTIF(Risks!F:F,"Inactive") -> 7 | H14: Closed Issues: | I14: =COUNTIF(Issues!D:D,"Closed") -> 3 | K14: Delayed: | L14: =COUNTIF(Dependencies!G:G,"Delayed") -> 2
B15: In Progress: | C15: =COUNTIF('Assumptions-Actions'!G:G,"In Progress") -> 1 | E15: Escalated to Issue: | F15: =COUNTIF(Risks!F:F,"Escalated to Issue") -> 1 | H15: Critical Impact: | I15: =COUNTIF(Issues!E:E,"Critical") -> 4 | K15: Active/Planned: | L15: =COUNTIF(Dependencies!G:G,"Active")+COUNTIF(Dependencies!G:G,"Planned") -> 0
B16: Active: | C16: =COUNTIF('Assumptions-Actions'!G:G,"Active") -> 0 | E16: Critical Priority: | F16: =COUNTIF(Risks!G:G,"Critical") -> 7 | H16: High Impact: | I16: =COUNTIF(Issues!E:E,"High") -> 1
B17: Completion Rate: | C17: =IF(C12>0,TEXT(C13/C12,"0%"),"N/A") -> 54% | E17: High Priority: | F17: =COUNTIF(Risks!G:G,"High") -> 3
B19: Project Health Indicators
B21: Active Critical Risks: | C21: =COUNTIFS(Risks!F:F,"Active",Risks!G:G,"Critical")+COUNTIFS(Risks!F:F,"Escalated to Issue",Risks!G:G,"Critical") -> 1 | E21: ⚠️ Items Requiring Attention:
B22: Active High Risks: | C22: =COUNTIFS(Risks!F:F,"Active",Risks!G:G,"High")+COUNTIFS(Risks!F:F,"Escalated to Issue",Risks!G:G,"High") -> 2 | E22: Delayed Actions: | F22: =COUNTIF('Assumptions-Actions'!G:G,"Delayed") -> 8
B23: Open Critical Issues: | C23: =COUNTIFS(Issues!D:D,"Active",Issues!E:E,"Critical") -> 1 | E23: Overdue Items: | F23: =COUNTIF('Assumptions-Actions'!M:M,">0") -> 0
B24: Delayed Dependencies: | C24: =COUNTIF(Dependencies!G:G,"Delayed") -> 2 | E24: Escalated Risks: | F24: =COUNTIF(Risks!F:F,"Escalated to Issue") -> 1

Sheet Assumptions-Actions
A1: # | B1: Raised Date | C1: Raised By | D1: Assupmtion / Action Description | E1: Type | F1: Owner | G1: Status | H1: Dependency | I1: Due Date | J1: Revised Due Date | K1: Closed Date | L1: History Comments / Progress | M1: Days Overdue | N1: Status Flag
A2: A-001 | B2: 46007 | C2: Netways/SAMI | D2: اجتماع بدء المشروع Kick-off | E2: Action | F2: Muath Albkr | G2: Completed | H2: None | I2: 46007 | J2: None | K2: 46007 | M2: =IF(AND(G2="Delayed",OR(I2<>"",I2<>"None")),IF(J2<>"",IF(J2<>"None",MAX(0,TODAY()-J2),MAX(0,TODAY()-I2)),MAX(0,TODAY()-I2)),"") | N2: =IF(G2="Completed","✓",IF(G2="Delayed","⚠",IF(G2="In Progress","→",IF(G2="Active","●","")))) -> ✓
A3: A-002 | B3: 46007 | C3: Netways/SAMI | D3: الاجتماع مع المديرية العامة للسجون وعرض متطلبات البنية التحتية ومناقشة كيفية الربط مع الجهات الخارجية والداخلية. | E3: Action | F3: Muath Albkr | G3: Completed | H3: None | I3: 46009 | J3: None | K3: 46009 | M3: =IF(AND(G2="Delayed",OR(I2<>"",I2<>"None")),IF(J2<>"",IF(J2<>"None",MAX(0,TODAY()-J2),MAX(0,TODAY()-I2)),MAX(0,TODAY()-I2)),"") | N3: =IF(G2="Completed","✓",IF(G2="Delayed","⚠",IF(G2="In Progress","→",IF(G2="Active","●","")))) -> ✓
A4: A-003 | B4: 46007 | C4: Netways | D4: إستلام وثائق مخطط سير العمل للخدمات المطلوبة | E4: Action | F4: Muath Albkr | G4: Completed | H4: None | I4: 46015 | J4: None | K4: 46015 | M4: =IF(AND(G2="Delayed",OR(I2<>"",I2<>"None")),IF(J2<>"",IF(J2<>"None",MAX(0,TODAY()-J2),MAX(0,TODAY()-I2)),MAX(0,TODAY()-I2)),"") | N4: =IF(G2="Completed","✓",IF(G2="Delayed","⚠",IF(G2="In Progress","→",IF(G2="Active","●","")))) -> ✓
A5: A-004 | B5: 46008 | C5: Netways | D5: بدء مراجعة الوثائق التي تم إستلامها والبدء بإعداد وثيقة (RTM) | E5: Action | F5: Mohammed Aleidi | G5: Completed | H5: None | I5: 46010 | K5: 46010 | M5: =IF(AND(G2="Delayed",OR(I2<>"",I2<>"None")),IF(J2<>"",IF(J2<>"None",MAX(0,TODAY()-J2),MAX(0,TODAY()-I2)),MAX(0,TODAY()-I2)),"") | N5: =IF(G2="Completed","✓",IF(G2="Delayed","⚠",IF(G2="In Progress","→",IF(G2="Active","●","")))) -> ✓
A6: A-005 | B6: 46008 | D6: مشاركة وثيقة (RTM) مع فريق سامي | E6: Action | F6: Mohammed Aleidi | G6: Completed | H6: None | I6: 46026 | J6: 46028 | K6: 46028 | M6: =IF(AND(G2="Delayed",OR(I2<>"",I2<>"None")),IF(J2<>"",IF(J2<>"None",MAX(0,TODAY()-J2),MAX(0,TODAY()-I2)),MAX(0,TODAY()-I2)),"") | N6: =IF(G2="Completed","✓",IF(G2="Delayed","⚠",IF(G2="In Progress","→",IF(G2="Active","●","")))) -> ✓
A7: A-006 | B7: 46007 | C7: Netways | D7: إستلام النسخة الأولية من وثيقة تحليل أصحاب المصلحة | E7: Action | F7: Muath Albkr | G7: Completed | H7: None | J7: None | K7: 46015 | M7: =IF(AND(G2="Delayed",OR(I2<>"",I2<>"None")),IF(J2<>"",IF(J2<>"None",MAX(0,TODAY()-J2),MAX(0,TODAY()-I2)),MAX(0,TODAY()-I2)),"") | N7: =IF(G2="Completed","✓",IF(G2="Delayed","⚠",IF(G2="In Progress","→",IF(G2="Active","●","")))) -> ✓
A8: A-007 | B8: 46007 | C8: Netways | D8: إعداد خطة المشروع الأولية وبدء التحضير لمرحلة تحليل متطلبات الأعمال | E8: Action | F8: Tawah Alsindi | G8: Completed | H8: None | I8: 46023 | J8: None | K8: 46023 | M8: =IF(AND(G2="Delayed",OR(I2<>"",I2<>"None")),IF(J2<>"",IF(J2<>"None",MAX(0,TODAY()-J2),MAX(0,TODAY()-I2)),MAX(0,TODAY()-I2)),"") | N8: =IF(G2="Completed","✓",IF(G2="Delayed","⚠",IF(G2="In Progress","→",IF(G2="Active","●","")))) -> ✓
A9: A-008 | B9: 46023 | C9: Netways | D9: ترتيب جلسات تحليل متطلبات الأعمال | E9: Action | F9: Muath Albkr | G9: Completed | H9: None | I9: 46026 | J9: None | K9: 46033 | L9: 7 يناير: تم التصعيد بأن التأخير في جلسات نقل المعرفه يؤثر على البدء في تحديد وتحليل خدمات الـ MVP وإغلاق مرحلة التحليل | M9: =IF(AND(G2="Delayed",OR(I2<>"",I2<>"None")),IF(J2<>"",IF(J2<>"None",MAX(0,TODAY()-J2),MAX(0,TODAY()-I2)),MAX(0,TODAY()-I2)),"") | N9: =IF(G2="Completed","✓",IF(G2="Delayed","⚠",IF(G2="In Progress","→",IF(G2="Active","●","")))) -> ✓
A10: A-009 | B10: 46023 | D10: عقد جلسات نقل المعرفة لكافة الخدمات مع فريق يونيكوم | E10: Action | F10: Muath Albkr | G10: Completed | H10: A-008 | I10: 46033 | J10: None | K10: 46037 | L10: 11 يناير: تم البدء بجلسات نقل المعرفه 15 يناير: تم الأنتهاء من جلسات نقل المعرفه لحميع الخدمات وتحديد الخدمات المندرجة تحت نطاق المشروع والخدمات التي تم استبعادها وتم الـتأكيد من المديرية بالخدمات المستعبده من نطاق المشروع | M10: =IF(AND(G2="Delayed",OR(I2<>"",I2<>"None")),IF(J2<>"",IF(J2<>"None",MAX(0,TODAY()-J2),MAX(0,TODAY()-I2)),MAX(0,TODAY()-I2)),"") | N10: =IF(G2="Completed","✓",IF(G2="Delayed","⚠",IF(G2="In Progress","→",IF(G2="Active","●","")))) -> ✓
A11: A-010 | B11: 46023 | C11: Netways | D11: عقد جلسات تحليل متطلبات الاعمال الغير الوظيفية للمرحلة الأولى (MVP) مع فريق المديرية | E11: Action | F11: Muath Albkr | G11: Completed | H11: A-009 | I11: 46027 | J11: 46056 | L11: 20 يناير:تمت مناقشة تأخر المديرية في مشاركة الحقول والنماذج المتعلقة بالخدمات خلال الاجتماع الأسبوعي مع فريق سامي، حيث تم الاتفاق على اتخاذ الإجراءات اللازمة والتنسيق لعقد اجتماعات مع الإدارات المعنية بهدف استكمال الخدمات الغير وظيفية 20 يناير: تمت مناقشة تأثير التأخير في مشاركة الحقول والنماذج على الجدول الزمني المعتمد، وما يترتب عليه من تأخير محتمل في تسليم خدمات المرحلة الأولى (MVP). 25 يناير: تم عقد اجتماع مع المساعد للعمليات، حيث تمت مناقشة ضرورة مشاركة النماذج وبيانات الـ Metadata المطلوبة لخدمات الـ MVP، بالإضافة إلى مناقشة طلبات تعديل مسارات الإجراءات التي سبق اعتمادها والموافقة عليها خلال مرحلة التحليل. 2 فبراير: تم عقد اجتماع مع فريق المديرية د. نمر، وتمت مناقشة التحديات القائمة، مع التأكيد على أهمية وضرورة مشاركة النماذج والحقول المطلوبة لخدمات الـ MVP | M11: =IF(AND(G2="Delayed",OR(I2<>"",I2<>"None")),IF(J2<>"",IF(J2<>"None",MAX(0,TODAY()-J2),MAX(0,TODAY()-I2)),MAX(0,TODAY()-I2)),"") | N11: =IF(G2="Completed","✓",IF(G2="Delayed","⚠",IF(G2="In Progress","→",IF(G2="Active","●","")))) -> ✓
A12: A-011 | B12: 46023 | C12: Netways | D12: خدمات نطاق المشروع | E12: Action | F12: Muath Albkr/Tawah Alsindi | G12: Completed | H12: A-009 | I12: 46027 | J12: None | K12: 46037 | L12: 11 يناير: تمت مشاركة قائمة بالخدمات المستخلصة من الوثائق المتوفرة، مع توضيح الخدمات التي تفتقر إلى وثائق متطلبات الأعمال مكتمله. وبأنتظار تحديد الخدمات التي يجب إدراجها أو استبعادها من النطاق من فريق يونيكوم 15 يناير: تم تحديد الخدمات المندرجة تحت نطاق المشروع والخدمات التي تم استبعادها وتم الـتأكيد من المديرية بالخدمات المستعبده من نطاق المشروع 25 يناير: تم التأكيد على الخدمات المتفق عليها، وما تم توثيقه مسبقًا كإجراءات عمل رسمية، إضافة إلى الخدمات التي سيتم أتمتتها ضمن نطاق المشروع | M12: =IF(AND(G2="Delayed",OR(I2<>"",I2<>"None")),IF(J2<>"",IF(J2<>"None",MAX(0,TODAY()-J2),MAX(0,TODAY()-I2)),MAX(0,TODAY()-I2)),"") | N12: =IF(G2="Completed","✓",IF(G2="Delayed","⚠",IF(G2="In Progress","→",IF(G2="Active","●","")))) -> ✓
A13: A-012 | B13: 46007 | C13: Netways | D13: مشاركة وثيقة معمارية الحلول | E13: Action | F13: Moataz Alfarajah | G13: Completed | H13: None | I13: 46009 | J13: 46029 | K13: 46029 | L13: 18 ديسمبر: تمت مشاركة وثيقة هيلكلية الحلول مع فريق سامي 22 ديسمبر: تم تحديث الوثيقة ومشاركتها 7 يناير: تمت مشاركة الوثيقة بعد التحديث الأخير | M13: =IF(AND(G2="Delayed",OR(I2<>"",I2<>"None")),IF(J2<>"",IF(J2<>"None",MAX(0,TODAY()-J2),MAX(0,TODAY()-I2)),MAX(0,TODAY()-I2)),"") | N13: =IF(G2="Completed","✓",IF(G2="Delayed","⚠",IF(G2="In Progress","→",IF(G2="Active","●","")))) -> ✓
A14: A-013 | B14: 46023 | C14: Netways | D14: توفير جميع الخدمات مع تحديد نقاط التكامل لكل خدمة | E14: Action | F14: Muath Albkr | G14: Completed | H14: None | I14: 46033 | J14: None | K14: 46037 | L14: 15 يناير: تمت مشاركة جميع الخدمات مع تحديد نقاط التكامل لكل خدمة | M14: =IF(AND(G2="Delayed",OR(I2<>"",I2<>"None")),IF(J2<>"",IF(J2<>"None",MAX(0,TODAY()-J2),MAX(0,TODAY()-I2)),MAX(0,TODAY()-I2)),"") | N14: =IF(G2="Completed","✓",IF(G2="Delayed","⚠",IF(G2="In Progress","→",IF(G2="Active","●","")))) -> ✓
A15: A-014 | B15: 46023 | C15: Netways | D15: توفير صلاحيات الوصول الىS-Cloud | E15: Action | F15: Muath Albkr/PGD | G15: Delayed | H15: None | I15: 46027 | J15: 46056 | L15: 20 يناير: تم تصعيد الموضوع على ضرورة توفير الصلاحيات والاجتماع مع الفريق التقني في المديرية | M15: =IF(AND(G2="Delayed",OR(I2<>"",I2<>"None")),IF(J2<>"",IF(J2<>"None",MAX(0,TODAY()-J2),MAX(0,TODAY()-I2)),MAX(0,TODAY()-I2)),"") | N15: =IF(G2="Completed","✓",IF(G2="Delayed","⚠",IF(G2="In Progress","→",IF(G2="Active","●","")))) -> ✓
A16: A-015 | B16: 46023 | C16: Netways | D16: عقد اجتماعات تقنية مع فريق البنية التحتية في المديرية للتجهيز لبيئات العمل التطويرية والتشغيلية | E16: Action | F16: Muath Albkr/PGD | G16: Delayed | H16: A-014 | I16: 46028 | J16: 46056 | L16: 20 يناير: تمت استلام الخوادم من قبل المديرية، حيث تبين أنها لا تغطي جميع البيئات المطلوبة، إضافة إلى أن هذه الخوادم غير مخصصة بشكل واضح لأي بيئة محددة (تطوير، اختبار، أو تشغيل) وتمت متاقشتها مع فريق سامي لأخذ الأجراء اللازم 25 يناير:تم عقد اجتماع مع فريق البنية التحتية، حيث تم الاتفاق على تزويد بيئة التطوير بالخوادم بعد تطبيق التحديثات حسب وثيقة الحل المعماري والتصميم المعتمدة 3 فبراير: توفير مهندس من قبل الشركة للعمل بشكل مباشر مع فريق البنية التحتية للمديرية لضمان تسريع تجهيز البيئات ومعالجة أي معوقات تقنية 9 فبراير: تم الأجتماع مع فريق المديرية وفريق البنية التحتية بتاريخ 8 فبراير وتمت مشاركة ملف إكسل يتضمن الأسماء الفعلية وعناوين IP المتعلقة بالأنظمة لكل من البيئة التطويرية والبيئة التجريبية و مشاركة ملف إكسل آخر يتضمن المنافذ الخاصة بالنظام لكل من البيئة التطويرية والبيئة التجريبية 10 فبراير: بعد تأكيد وتجهيز تحديثات بنية الخوادم والمنافذ المطلوبة، قام فريق تقنية المعلومات بتخصيص خادمين لنظام آخر. ونتيجةً لذلك، طلبنا تحديث البنية الخاصة بنا لتتوافق مع هذا التغيير، وسيتم إعادة إرسال المستندات محدثه وفقًا لذلك 05 مارس: تم التأكيد من قبل فريق البنية التحتية في المديرية بفتح جميع المنافذ المطلوبة للبيئة الأختبارية والتشغيلية. 09 مارس: تمت مراجعة المنافذ من قبل نتويز حيث تبين ان معضم المنافذ لاتزال غير مفعلة31 31 مارس: تمت مناقشة المتطلبات التقنية مع فريق البنية التحتية للبدء في تثبيت نظام CRM والتي تشمل تجهيز خادم ADFS ، إعدادات SPN ، تجهيز المنافذ 7 أبريل: تم الـتأكيد من قبل المديية بجهوزية البيئة التطويرية | M16: =IF(AND(G2="Delayed",OR(I2<>"",I2<>"None")),IF(J2<>"",IF(J2<>"None",MAX(0,TODAY()-J2),MAX(0,TODAY()-I2)),MAX(0,TODAY()-I2)),"") | N16: =IF(G2="Completed","✓",IF(G2="Delayed","⚠",IF(G2="In Progress","→",IF(G2="Active","●","")))) -> ✓
A17: A-016 | B17: 46023 | C17: Netways | D17: الأنتهاء من تحضير بيئات العمل التطويرية، الأختبارية والتشغيلية | E17: Action | F17: Muath Albkr/PGD | G17: Delayed | H17: A-015 | I17: 46042 | M17: =IF(AND(G2="Delayed",OR(I2<>"",I2<>"None")),IF(J2<>"",IF(J2<>"None",MAX(0,TODAY()-J2),MAX(0,TODAY()-I2)),MAX(0,TODAY()-I2)),"") | N17: =IF(G2="Completed","✓",IF(G2="Delayed","⚠",IF(G2="In Progress","→",IF(G2="Active","●","")))) -> ✓
A18: A-017 | C18: Netways | D18: مشاركة وثيقة الوضع الحالي لجودة الخدمات و وثيقة الوضع الحالي لجودة الخدمات من قبل فريق سامي | E18: Action | F18: Muath Albkr | G18: Completed | H18: None | I18: None | J18: None | K18: 46036 | M18: =IF(AND(G2="Delayed",OR(I2<>"",I2<>"None")),IF(J2<>"",IF(J2<>"None",MAX(0,TODAY()-J2),MAX(0,TODAY()-I2)),MAX(0,TODAY()-I2)),"") | N18: =IF(G2="Completed","✓",IF(G2="Delayed","⚠",IF(G2="In Progress","→",IF(G2="Active","●","")))) -> ✓
A19: A-018 | B19: 46023 | C19: Netways/SAMI | D19: تحديد خدمات MVP بعد جلسات نقل المعرفة | E19: Action | F19: Muath Albkr/Tawah Alsindi | G19: Completed | H19: A-009 | I19: 46027 | K19: 46042 | L19: 14 يناير: تم تحديد خدمات ال MVP (طلب نقل، طلب خروج للضرورة وطلب الشكاوي والاقتراحات) 25 يناير: وتم الاتفاق على أن تكون جميع خدمات MVP تابعة لإدارة مساعد العمليات. (طلب نقل، طلب خروج للضرورة وطلب الشكاوي والاقتراحات) | M19: =IF(AND(G2="Delayed",OR(I2<>"",I2<>"None")),IF(J2<>"",IF(J2<>"None",MAX(0,TODAY()-J2),MAX(0,TODAY()-I2)),MAX(0,TODAY()-I2)),"") | N19: =IF(G2="Completed","✓",IF(G2="Delayed","⚠",IF(G2="In Progress","→",IF(G2="Active","●","")))) -> ✓
A20: A-019 | B20: 46042 | C20: Netways/SAMI | D20: أستكمال جمع المتطلبات الغير الوظيفية لخدمات MVP ومشاركة وثيقة SRS | E20: Action | F20: Mohammed Aleidi | G20: Completed | H20: A-010 | I20: 46036 | K20: 46077 | L20: 12 يناير: بأنتظار عقد جلسات مع المديرية لأنهاء متطلبات الأعمال الغير وظيفية وعكسها على وثيقة SRS 20 يناير -27 يناير: تم مناقشة هذا التحدي والتصعيد مع الفرق المعنية في المديرية 03 فبراير: تم مشاركة ملف يتضمن الأدارات المتعلقة بكل خدمة على ان يتم عقد جلسات مع الأدارات المعنية، وتم التأكيد من قبل فريق المديرية على أن تبدأ الجلسات بتاريخ 3 فبراير 15 فبراير: تم الأجتماع مع فريق المديرية وتم أعتماد النماذج والحقول لخدمات MVP 19 فبراير: تمت مشاركة وثيقة متطلبات الأعمال التفصيلة للمراجعة والأعتماد 24 فبراير: تم أعتماد الوثيقة من قبل فريق المديرية | M20: =IF(AND(G2="Delayed",OR(I2<>"",I2<>"None")),IF(J2<>"",IF(J2<>"None",MAX(0,TODAY()-J2),MAX(0,TODAY()-I2)),MAX(0,TODAY()-I2)),"") | N20: =IF(G2="Completed","✓",IF(G2="Delayed","⚠",IF(G2="In Progress","→",IF(G2="Active","●","")))) -> ✓
A21: A-020 | B21: 46042 | C21: Netways | D21: مشاركة آلية الربط مع البصمة (آلية دخول النزيل) | E21: Action | F21: Muath Albkr | G21: Delayed | H21: None | I21: 46027 | J21: 46056 | L21: 02 فبراير: تم التأكيد في الأجتماع اليومي من المديرية بتزويد الشركة بملف القضايا المستثناة من طلبات النقل والخروج، وقائمة المراكز التأهيلية المعتمدة، وآلية الربط مع البصمة (آلية دخول النزيل)، إضافة إلى مشاركة النماذج والحقول الخاصة بخدمتي طلب النقل وطلب الخروج للضرورة 11 مارس: عقد اجتماع مع المهندس عمر من فريق البنية التحتية ومناقشة آلية استخدام البصمة، وتم الاتفاق على تنفيذها أثناء مرحلة التنفيذ لعدم توفر توثيق فني لالية الاستخدام. 05 أبريل: تم عقد اجتماع مع فريق البنية التحتية في المديرية لاستعراض آخر التحديثات التقنية، ومناقشة آلية البصمة ومتطلبات التكامل | M21: =IF(AND(G2="Delayed",OR(I2<>"",I2<>"None")),IF(J2<>"",IF(J2<>"None",MAX(0,TODAY()-J2),MAX(0,TODAY()-I2)),MAX(0,TODAY()-I2)),"") | N21: =IF(G2="Completed","✓",IF(G2="Delayed","⚠",IF(G2="In Progress","→",IF(G2="Active","●","")))) -> ✓
A22: A-021 | B22: 46042 | C22: Netways | D22: تأكيد متطلبات خدمة البيت العائلي | E22: Action | F22: Muath Albkr | G22: Completed | H22: None | I22: 46027 | J22: 46056 | L22: خلال جلسات التسليم مع فريق Unickomm Platformation، أفاد الفريق بأن المتطلبات النهائية لهاتين الخدمتين "البيت العائلي وتسليم الأمانات" لم يتم توفيرها فيما يخص خدمة «البيت العائلي»، سيتم مناقشة المتطلبات النهائية مع الجهة المختصة خلال جلسات المتطلبات غير الوظيفية، حيث إنها غير جاهزة حاليًا. كما أوصت PGD بجدولة هذه المناقشة لتكون الاجتماع الأخير 08 مارس: عقد أجتماع مع فريق المديرية لخدمة البيت العائلي حيث تم مشاركة الملفات الخاصة بخدمة البيت العائلي وانتظار المراجعة مع الادارة المعنية (مسار العمل) 12 أبريل: تم أعتماد متطلبات الخدمة من قبل المديرية | M22: =IF(AND(G2="Delayed",OR(I2<>"",I2<>"None")),IF(J2<>"",IF(J2<>"None",MAX(0,TODAY()-J2),MAX(0,TODAY()-I2)),MAX(0,TODAY()-I2)),"") | N22: =IF(G2="Completed","✓",IF(G2="Delayed","⚠",IF(G2="In Progress","→",IF(G2="Active","●","")))) -> ✓
A23: A-022 | B23: 46042 | C23: Netways | D23: توضيح آلية عمل خدمة طلب تسليم الأمانات | E23: Action | F23: Muath Albkr | G23: Completed | H23: None | I23: 46027 | J23: 46056 | L23: 03 فبراير: تم تمت مناقشة خدمة تسليم الأمانات مع المديرية في الأجتماع اليومي، حيث تقرر وضعها حاليًا في حالة On Hold إلى حين تأكيد المديرية حول ما إذا كانت ستندرج ضمن خدمات النزيل أو ضمن مشروع خارجي آخر 26 فبراير: تم التأكيد من قبل المديرية بأنه يتم تطوير عمل الخدمة مقتصراً على الأمانات العينية فقط | M23: =IF(AND(G2="Delayed",OR(I2<>"",I2<>"None")),IF(J2<>"",IF(J2<>"None",MAX(0,TODAY()-J2),MAX(0,TODAY()-I2)),MAX(0,TODAY()-I2)),"") | N23: =IF(G2="Completed","✓",IF(G2="Delayed","⚠",IF(G2="In Progress","→",IF(G2="Active","●","")))) -> ✓
A24: A-023 | B24: 46042 | C24: Netways | D24: التنسيق لاجتماع مع إدارة المساعد للعمليات (الشكاوى) | E24: Action | F24: Muath Albkr | G24: Completed | H24: None | I24: 46027 | J24: 46055 | L24: 02 فبراير: تم الاتفاق في الأجتماع اليومي على تزويد المديرية بالنماذج والحقول اللازمة للمراجعة والاعتماد 03 فبراير: تم أعتماد حقول الشكاوي والأقتراحات | M24: =IF(AND(G2="Delayed",OR(I2<>"",I2<>"None")),IF(J2<>"",IF(J2<>"None",MAX(0,TODAY()-J2),MAX(0,TODAY()-I2)),MAX(0,TODAY()-I2)),"") | N24: =IF(G2="Completed","✓",IF(G2="Delayed","⚠",IF(G2="In Progress","→",IF(G2="Active","●","")))) -> ✓
A25: A-024 | B25: 46049 | C25: Netways/SAMI | D25: مشاركة تصنيف القضايا والقضايا المستثناة | E25: Action | F25: Muath Albkr | G25: Completed | H25: None | I25: 46027 | J25: 46056 | L25: 02 فبراير: تم التأكيد في الأجتماع اليومي من المديرية بتزويد الشركة بملف القضايا المستثناة من طلبات النقل والخروج، وقائمة المراكز التأهيلية المعتمدة، وآلية الربط مع البصمة (آلية دخول النزيل)، إضافة إلى مشاركة النماذج والحقول الخاصة بخدمتي طلب النقل وطلب الخروج للضرورة | M25: =IF(AND(G2="Delayed",OR(I2<>"",I2<>"None")),IF(J2<>"",IF(J2<>"None",MAX(0,TODAY()-J2),MAX(0,TODAY()-I2)),MAX(0,TODAY()-I2)),"") | N25: =IF(G2="Completed","✓",IF(G2="Delayed","⚠",IF(G2="In Progress","→",IF(G2="Active","●","")))) -> ✓
A26: A-025 | B26: 46049 | C26: Netways/SAMI | D26: مشاركة المراكز التأهيلية المعتمدة | E26: Action | F26: Muath Albkr | G26: Completed | H26: None | I26: 46027 | J26: 03/02/2026 10/02/2026 | K26: 46090 | L26: 02 فبراير: تم التأكيد في الأجتماع اليومي من المديرية بتزويد الشركة بملف القضايا المستثناة من طلبات النقل والخروج، وقائمة المراكز التأهيلية المعتمدة، وآلية الربط مع البصمة (آلية دخول النزيل)، إضافة إلى مشاركة النماذج والحقول الخاصة بخدمتي طلب النقل وطلب الخروج للضرورة 09 مارس: تمت مشاركة المراكز التأهيلية المعتمدة من قبل المديرية | M26: =IF(AND(G2="Delayed",OR(I2<>"",I2<>"None")),IF(J2<>"",IF(J2<>"None",MAX(0,TODAY()-J2),MAX(0,TODAY()-I2)),MAX(0,TODAY()-I2)),"") | N26: =IF(G2="Completed","✓",IF(G2="Delayed","⚠",IF(G2="In Progress","→",IF(G2="Active","●","")))) -> ✓
A27: A-026 | B27: 46049 | C27: Netways | D27: مراجعة واعتماد وثيقة ميثاق المشروع | E27: Action | F27: Muath Albkr | G27: Completed | H27: None | I27: 46027 | J27: 46056 | K27: 46063 | M27: =IF(AND(G2="Delayed",OR(I2<>"",I2<>"None")),IF(J2<>"",IF(J2<>"None",MAX(0,TODAY()-J2),MAX(0,TODAY()-I2)),MAX(0,TODAY()-I2)),"") | N27: =IF(G2="Completed","✓",IF(G2="Delayed","⚠",IF(G2="In Progress","→",IF(G2="Active","●","")))) -> ✓
A28: A-027 | B28: 46034 | C28: Netways | D28: مشاركة "النماذج والحقول" الخاصة بطلب النقل وطلب الخروج للضرورة والشكاوي والأقتراحات، من قبل إدارة مساعد العمليات من قبل المديرية | E28: Action | F28: Muath Albkr | G28: Completed | H28: None | I28: 46027 | J28: 46056 | K28: 46068 | L28: 20 يناير: تمت مناقشة التأخير في مشاركة الحقول و والنماذج المتعلقة بالخدمات من قبل المديرية في الأجتماع الأسبوعي مع فريق سامي لأتخاذ الأجراء والأجتماع مع الأدارات لأنهاء الخدمات الوظيفية 20 يناير: تمت مناقشة التأخير في مشاركة الحقول و والنماذج والتأخير المترتب على الجدول الزمني لتسليم خدمات MVP 25 يناير: تم عقد اجتماع مع المساعد للعمليات، ومناقشة تسليم النماذج وال Metadata المطلوبة لخدمات MVP ومناقشة طلبات لتعديل مسارات الإجراءات التي تم اعتمادها والموافقة عليها مسبقًا خلال مرحلة التحليل 2 فبراير: تم الأجتماع مع فريق المديرية د. نمر ومناقشة التحديات وضوروة مشاركة النماذج والحقول لخدمات MVP 3 فبراير: تم مشاركة وأعتماد حقول خدمة الشكاوي والأقتراحات 8 فبراير: تمت مشاركة النماذج والحقول لخدمة النقل والخروج للضروره وبأنتظار أعتمادها والتعديلات المتعلقة بها وبعد المراجعة وردت عدة ملاحظات من المديرية تتطلب تعديل سير العمل وتقسيم سير العمل إلى مسارين مختلفين؛، مع الاستمرار في إضافة ملاحظات جديدة للتعديل 10 فبراير: تم مناقشة التأخير على أعتماد التعديلات على خدمة النقل والخروج للضروره مع فريق المديرية وضرورة الحصول على الأعتماد بشكل عاجل اليوم، لم يتمكن فريق التنفيذ من الحصول على الأعتماد بسبب عدم تواجد إدارة مساعد العمليات 15 قبراير: تم الأجتماع مع فريق المديرية و الأتفاق على البدء بتنفيذ نطاق MVP ، ويشمل ذلك الخدمات بناًء على المعلومات المتاحة حاليا التالية: الشكاوي واالقتراحات – النقل – طلب الخروج. | M28: =IF(AND(G2="Delayed",OR(I2<>"",I2<>"None")),IF(J2<>"",IF(J2<>"None",MAX(0,TODAY()-J2),MAX(0,TODAY()-I2)),MAX(0,TODAY()-I2)),"") | N28: =IF(G2="Completed","✓",IF(G2="Delayed","⚠",IF(G2="In Progress","→",IF(G2="Active","●","")))) -> ✓
A29: A-028 | B29: 46042 | C29: Netways | D29: الأنتهاء من تصميم نظام إجراءات نزلاء السجون (UI/UX & Story Board for MFP Services) MVP &Full scope | E29: Milestone | F29: Netways | G29: Completed | H29: A-019 | I29: 46035 | L29: 15 فبراير: تم البدء بتصميم واجهات النطام لخدمة الشكاوي والأقتراحات 26 فبراير: تمت مشاركة التصاميم للبوابة والكيوسك لخدمات MVP للمراجعة والأعتماد. تم الموافقة على التصاميم من قبل المديرية وفريق سامي 12 مارس: تمت مشاركة التصاميم للبوابة والكيوسك لخدمات التعليم والتدريب والتشغيل للمراجعة والأعتماد. 26 مارس: تمت الانتهاء من تصاميم واجهات البوابة وجهاز الخدمة الذاتية لجميع خدمات المشروع (Full Scope) ومشاركتها مع فريق سامي والمديرية للمراجعة والاعتماد 30 مارس: تم أعتماد جميع خدمات نطاق المشروع وتصاميم البوابة وجهاز الخدمة الذاتية من قبل فريق سامي والمديرية وبأنتئار خدماة البيت العائلي والزيارات | M29: =IF(AND(G2="Delayed",OR(I2<>"",I2<>"None")),IF(J2<>"",IF(J2<>"None",MAX(0,TODAY()-J2),MAX(0,TODAY()-I2)),MAX(0,TODAY()-I2)),"") | N29: =IF(G2="Completed","✓",IF(G2="Delayed","⚠",IF(G2="In Progress","→",IF(G2="Active","●","")))) -> ✓
A30: A-029 | B30: 46033 | C30: Netways | D30: التأكيد على أعتماد تطوير تطبيق الهاتف المحمول في نطاق المشروع او أعتماد أستعمال البوابة عن طريق الهاتف (Responsive design) | E30: Action | F30: Muath Albkr/PGD | G30: Delayed | H30: None | I30: 46027 | M30: =IF(AND(G2="Delayed",OR(I2<>"",I2<>"None")),IF(J2<>"",IF(J2<>"None",MAX(0,TODAY()-J2),MAX(0,TODAY()-I2)),MAX(0,TODAY()-I2)),"") | N30: =IF(G2="Completed","✓",IF(G2="Delayed","⚠",IF(G2="In Progress","→",IF(G2="Active","●","")))) -> ✓
A31: A-030 | B31: 46027 | C31: Netways | D31: اعتماد تصميم DGA من قبل المديرية. | E31: Action | F31: Muath Albkr/PGD | G31: Completed | H31: None | I31: 46027 | K31: 46029 | M31: =IF(AND(G2="Delayed",OR(I2<>"",I2<>"None")),IF(J2<>"",IF(J2<>"None",MAX(0,TODAY()-J2),MAX(0,TODAY()-I2)),MAX(0,TODAY()-I2)),"") | N31: =IF(G2="Completed","✓",IF(G2="Delayed","⚠",IF(G2="In Progress","→",IF(G2="Active","●","")))) -> ✓
A32: A-031 | B32: 46037 | C32: Netways | D32: خدمات إدارة التأهيل والأصلاح ( التعليم والتدريب والتشغيل) | E32: Action | F32: Muath Albkr/PGD | G32: Completed | H32: None | I32: 46051 | J32: 46063 | K32: 46069 | L32: 4 فبراير: تم الأجتماع مع إدارة الأصلاح والتأهيل ومناقشة خدمة التشغيل، التدريب و التعليم ومناقشة التحليل الفني والتقني والية التنفيذ. وبأنتظار تزويدنا بالحقول والنماذج المتعلقة بكل خدمة 12 فبراير: تمت مشاركة الحقول والنماذح للتشغيل والتدريب والتعليم من قبل المديرية 16 فبراير: تم أعتماد ملفات خدمات التشغيل والتدريب والتعليم 03: تمت مشاركة وثيقة الأعمال التفصيلية لخدمات التعليم والتدريب والتشغيل وتم أعتمادها من قبل المديرية 12مارس: تمت مشاركة التصاميم للبوابة والكيوسك لخدمات التعليم والتدريب والتشغيل للمراجعة والأعتماد من قبل فريق سامي | M32: =IF(AND(G2="Delayed",OR(I2<>"",I2<>"None")),IF(J2<>"",IF(J2<>"None",MAX(0,TODAY()-J2),MAX(0,TODAY()-I2)),MAX(0,TODAY()-I2)),"") | N32: =IF(G2="Completed","✓",IF(G2="Delayed","⚠",IF(G2="In Progress","→",IF(G2="Active","●","")))) -> ✓
A33: A-032 | B33: 46073 | C33: Netways | D33: وثيقة متطلبات الأعمال التفصيلية لخدمات حلقات تحفيظ القرآن الكريم، اختبارات القرآن الكريم, خدمة إمام أو مؤذن_ إدارة النوجية الأرشاد | E33: Action | F33: Muath Albkr/PGD | G33: Completed | H33: None | I33: 46051 | J33: 46078 | K33: 46113 | L33: 18 فبراير: تم عقد اجتماع مع فريق الإرشاد والتوجيه في المديرية ومناقشة خدمات تحفيظ القرآن، الاختبارات، الإمام والمؤذن ومراجعة النماذج 25 فبراير:تم أعتماد حلقات تحفيظ القرآن الكريم، اختبارات القرآن الكريم, خدمة إمام أو مؤذن 09 مارس: تمت ماشركة وثيقة متطلبات الأعمال التفصيلية مع فريق سامي للموافقه والأعتماد 1 أبريل: تم أعتماد الوثيقة من قبل المديرية | M33: =IF(AND(G2="Delayed",OR(I2<>"",I2<>"None")),IF(J2<>"",IF(J2<>"None",MAX(0,TODAY()-J2),MAX(0,TODAY()-I2)),MAX(0,TODAY()-I2)),"") | N33: =IF(G2="Completed","✓",IF(G2="Delayed","⚠",IF(G2="In Progress","→",IF(G2="Active","●","")))) -> ✓
A34: A-033 | B34: 46083 | C34: Netways | D34: الأنتهاء من تطوير نظام إجراءات نزلاء السجون (MVP) | F34: A.Aliwat & Motaz | G34: Delayed | H34: A-028 | I34: 29/02/2026 | J34: 46096 | L34: 02 مارس: تم البدء بتطوير خدمات الـ MVP 31 مارس: عقد جلسة عرض توضيحي لخدمة الشكاوى مع فريق المديرية وسامي 13 أبريل: تم اكتمال تطوير البوابة وجهاز الخدمة الذاتية لخدمات المرحلة الأولى (MVP) ، مع انتظار جاهزية التكامل من طرف المديرية ومشاركتها مع فريق الشركة 19 أبريل: عقد جلسة عرض توضيحي لخدمات MVP مع فريق المديرية وسامي ومشاركة بعض التعديلات للشركة لتنفيذها | M34: =IF(AND(G2="Delayed",OR(I2<>"",I2<>"None")),IF(J2<>"",IF(J2<>"None",MAX(0,TODAY()-J2),MAX(0,TODAY()-I2)),MAX(0,TODAY()-I2)),"") | N34: =IF(G2="Completed","✓",IF(G2="Delayed","⚠",IF(G2="In Progress","→",IF(G2="Active","●","")))) -> ✓
A35: A-034 | B35: 46090 | C35: Netways | D35: وثيقة متطلبات الأعمال التفصيلية لخدمة تسليم الأمانات وخدمات إدارة الرعاية الصحية | E35: Action | F35: Muath Albkr/PGD | G35: Completed | H35: None | I35: 46051 | K35: 46113 | L35: 09 مارس: تمت مشاركة وثيقة متطلبات الأعمال التفصيلية (SRS) الخاصة لخدمة تسليم الأمانات للمراجعة والأعتماد 25 مارس: تمت مشاركة وثيقة متطلبات الأعمال التفصيلية (SRS) الخاصة لخدمةالرعاية لصحية للمراجعة والأعتماد 25 مارس: تم أعتماد الوثيقة من قبل المديرية وفريق سامي 1 أبريل: تم أعتماد الوثيقة من قبل المديرية | M35: =IF(AND(G2="Delayed",OR(I2<>"",I2<>"None")),IF(J2<>"",IF(J2<>"None",MAX(0,TODAY()-J2),MAX(0,TODAY()-I2)),MAX(0,TODAY()-I2)),"") | N35: =IF(G2="Completed","✓",IF(G2="Delayed","⚠",IF(G2="In Progress","→",IF(G2="Active","●","")))) -> ✓
A36: A-035 | B36: 46093 | C36: Netways | D36: وثيقة متطلبات الأعمال التفصيلية (SRS) الخاصة لخدمات طلب نقل الى مركز تأهيلي, طلب نقل من مركز تأهيلي الى مركز تأهيلي آخر | E36: Action | F36: Muath Albkr/PGD | G36: Completed | H36: None | I36: 46051 | K36: 46113 | L36: 12 مارس: تمت مشاركة وثيقة متطلبات الأعمال التفصيلية (SRS) الخاصة لخدمات طلب نقل الى مركز تأهيلي, طلب نقل من مركز تأهيلي الى مركز تأهيلي آخر المندرج تحت الإدارة العامة للمراكز التأهيلية التخصصية للمراجعة والأعتماد 25 مارس: تم أعتماد الوثيقة من قبل فريق سامي 1 أبريل: تم أعتماد الوثيقة من قبل المديرية | M36: =IF(AND(G2="Delayed",OR(I2<>"",I2<>"None")),IF(J2<>"",IF(J2<>"None",MAX(0,TODAY()-J2),MAX(0,TODAY()-I2)),MAX(0,TODAY()-I2)),"") | N36: =IF(G2="Completed","✓",IF(G2="Delayed","⚠",IF(G2="In Progress","→",IF(G2="Active","●","")))) -> ✓
A37: A-036 | C37: Netways | D37: وثيقة متطلبات الأعمال التفصيلية (SRS) الخاصة لخدمة خدمة الزيارة العامة والزيارة المرئية خدمة البيت العائلي | E37: Action | F37: Muath Albkr/PGD | G37: Delayed | H37: None | I37: 46051 | L37: 18 مارس: تمت مشاركة نسخة مبدئية من وثيقة متطلبات الأعمال التفصيلية (SRS) 12 أبريل: تم أعتماد متطلبات خدمة البيت العائلي من قبل المديرية 05 أبريل: تم عقد اجتماع مع مسؤولي خدمة البيت العائلي لمراجعة النماذج ومتطلبات الأعمال التفصيلية للخدمة 13 أبريل: تمت مشاركة نسخة محدثة وعكس المتطلبات العتمدة على الوثيقة لخدمة البيت العائلي للأعتماد 15 أبريل: تم أعتماد وثيقة متطلبات الأ‘عمال التفصيلية لخدمة البيت العائلي | M37: =IF(AND(G2="Delayed",OR(I2<>"",I2<>"None")),IF(J2<>"",IF(J2<>"None",MAX(0,TODAY()-J2),MAX(0,TODAY()-I2)),MAX(0,TODAY()-I2)),"") | N37: =IF(G2="Completed","✓",IF(G2="Delayed","⚠",IF(G2="In Progress","→",IF(G2="Active","●","")))) -> ✓
A38: A-117 | B38: 46084 | C38: Netways | D38: وثيقة متطلبات الأعمال التفصيلية والتصمايم لخدمات التعليم والتدريب والتشغيل | E38: Action | F38: Muath Albkr/PGD | G38: Completed | H38: None | I38: 46051 | K38: 46096 | L38: 03 مارس: تمت ماشركة وثيقة متطلبات الأعمال التفصيلية مع فريق سامي للموافقه والأعتماد 04 مارس: تم أعتماد الوثيقة من قبل المديرية 12 مارس: تمت مشاركة تصاميم البوابة والكويسك للمراجعة والأعتماد 15 مارس: تم أعتماد الوثيقة من قبل المديرية | M38: =IF(AND(G2="Delayed",OR(I2<>"",I2<>"None")),IF(J2<>"",IF(J2<>"None",MAX(0,TODAY()-J2),MAX(0,TODAY()-I2)),MAX(0,TODAY()-I2)),"") | N38: =IF(G2="Completed","✓",IF(G2="Delayed","⚠",IF(G2="In Progress","→",IF(G2="Active","●","")))) -> ✓
A39: A-118 | B39: 46090 | C39: Netways | D39: وثيقة متطلبات الأعمال التفصيلية (SRS) الخاصة لخدمة تسليم الأمانات | E39: Action | F39: Muath Albkr/PGD | G39: Completed | H39: None | I39: 46051 | K39: 46113 | L39: 09 مارس: تمت مشاركة وثيقة متطلبات الأعمال التفصيلية (SRS) الخاصة لخدمة تسليم الأمانات للمراجعة والأعتماد 1 أبريل: تم أعتماد الوثيقة من قبل المديرية | M39: =IF(AND(G2="Delayed",OR(I2<>"",I2<>"None")),IF(J2<>"",IF(J2<>"None",MAX(0,TODAY()-J2),MAX(0,TODAY()-I2)),MAX(0,TODAY()-I2)),"") | N39: =IF(G2="Completed","✓",IF(G2="Delayed","⚠",IF(G2="In Progress","→",IF(G2="Active","●","")))) -> ✓
A40: A-119 | B40: 46093 | C40: Netways | D40: وثيقة متطلبات الأعمال التفصيلية (SRS) الخاصة لخدمات طلب نقل الى مركز تأهيلي, طلب نقل من مركز تأهيلي الى مركز تأهيلي آخر | E40: Action | F40: Muath Albkr/PGD | G40: Completed | H40: None | I40: 46051 | K40: 46113 | L40: 12 مارس: تمت مشاركة وثيقة متطلبات الأعمال التفصيلية (SRS) الخاصة لخدمات طلب نقل الى مركز تأهيلي, طلب نقل من مركز تأهيلي الى مركز تأهيلي آخر المندرج تحت الإدارة العامة للمراكز التأهيلية التخصصية للمراجعة والأعتماد 1 أبريل: تم أعتماد الوثيقة من قبل المديرية | M40: =IF(AND(G2="Delayed",OR(I2<>"",I2<>"None")),IF(J2<>"",IF(J2<>"None",MAX(0,TODAY()-J2),MAX(0,TODAY()-I2)),MAX(0,TODAY()-I2)),"") | N40: =IF(G2="Completed","✓",IF(G2="Delayed","⚠",IF(G2="In Progress","→",IF(G2="Active","●","")))) -> ✓
...

Sheet Dependencies
A1: No. | B1: Dependent Milestone/Task | C1: Dependency | D1: Dependency Owner Name | E1: Due Date | F1: Original Committed Date | G1: Status | H1: Revised Due Date | I1: Actual closing Date | J1: Impact Sum (days) + = Negative| - =Positive | K1: History Comments | L1: Days Until Due | M1: Status Flag
A2: 1 | B2: تحديد نطاق المرحلة الأولى (َMVP Scope) وتحديث خطة المشروع التفصيلية (البدء والتصور) | C2: الأنتهاء من جلسات نقل المعرفة لكافة الخدمات مع فريق يونيكوم | D2: Muath Albkr | E2: 46028 | F2: 46044 | G2: Closed | H2: 46044 | I2: 46044 | J2: +12 | L2: =IF(G2="Closed","Closed",IF(E2<>"",IF(E2<TODAY(),"Overdue",E2-TODAY()),"")) -> Closed | M2: =IF(G2="Closed","✓",IF(G2="Delayed","⚠ DELAYED",IF(AND(E2<>"",E2<TODAY()),"⛔ OVERDUE",IF(AND(E2<>"",E2-TODAY()<=7),"⏰ Due Soon","")))) -> ✓
A3: 2 | B3: تحديد نطاق المرحلة الأولى (َMVP Scope) وتحديث خطة المشروع التفصيلية (البدء والتصور) | C3: مناقشة خدمات MVP المطلوبة مع المديرية والاتفاق عليها | D3: Muath Albkr | E3: 46028 | F3: 46044 | G3: Closed | H3: 46044 | I3: 46044 | J3: +12 | L3: =IF(G2="Closed","Closed",IF(E2<>"",IF(E2<TODAY(),"Overdue",E2-TODAY()),"")) -> Closed | M3: =IF(G2="Closed","✓",IF(G2="Delayed","⚠ DELAYED",IF(AND(E2<>"",E2<TODAY()),"⛔ OVERDUE",IF(AND(E2<>"",E2-TODAY()<=7),"⏰ Due Soon","")))) -> ✓
A4: 3 | B4: تجهيز بيئات العمل التطويرية والتشغيلية وتفعيل رخص المنصة | C4: تزويد الشركة بصلاحيات الوصول اللازمة والتأكد من جاهزية جميع الخوادم المطلوبة مع عقد اجتماعات تقنية مع فريق البنية التحتية في المديرية للتجهيز لبيئات العمل التطويرية والتشغيلية | D4: Muath Albkr & PGD | E4: 46028 | F4: 46057 | G4: Delayed | H4: 12/02/2026 27/02/2026 | L4: =IF(G2="Closed","Closed",IF(E2<>"",IF(E2<TODAY(),"Overdue",E2-TODAY()),"")) -> Closed | M4: =IF(G2="Closed","✓",IF(G2="Delayed","⚠ DELAYED",IF(AND(E2<>"",E2<TODAY()),"⛔ OVERDUE",IF(AND(E2<>"",E2-TODAY()<=7),"⏰ Due Soon","")))) -> ✓
A5: 4 | B5: أستكمال جمع المتطلبات الغير وظيفية لخدمات MVP | C5: الأجتماع مع المعنيين في الأدارات من المديرية وتزويد الشركة بالحقول والنماذج لخدمات MVP | D5: Muath Albkr & PGD | E5: 46028 | F5: 46057 | G5: Closed | H5: 46064 | I5: 46068 | J5: +30 | L5: =IF(G2="Closed","Closed",IF(E2<>"",IF(E2<TODAY(),"Overdue",E2-TODAY()),"")) -> Closed | M5: =IF(G2="Closed","✓",IF(G2="Delayed","⚠ DELAYED",IF(AND(E2<>"",E2<TODAY()),"⛔ OVERDUE",IF(AND(E2<>"",E2-TODAY()<=7),"⏰ Due Soon","")))) -> ✓
A6: 5 | B6: تسليم وثيقة متطلبات الأعمال التفصيلية SRS لخدمات MVP | C6: أستكمال جمع المتطلبات الغير وظيفية لخدمات MVP | D6: Mohammed Aledi | E6: 46028 | F6: 46057 | G6: Closed | H6: - | I6: 46068 | J6: +42 | L6: =IF(G2="Closed","Closed",IF(E2<>"",IF(E2<TODAY(),"Overdue",E2-TODAY()),"")) -> Closed | M6: =IF(G2="Closed","✓",IF(G2="Delayed","⚠ DELAYED",IF(AND(E2<>"",E2<TODAY()),"⛔ OVERDUE",IF(AND(E2<>"",E2-TODAY()<=7),"⏰ Due Soon","")))) -> ✓
A7: 6 | B7: البدء في إعداد وثيقة تصميم الحل لخدمات MVP | C7: أعتماد وثيقة متطلبات الأعمال التفصيلية SRS | D7: Muath Albkr | E7: 46036 | F7: - | G7: Closed | H7: - | I7: 46077 | J7: +42 | L7: =IF(G2="Closed","Closed",IF(E2<>"",IF(E2<TODAY(),"Overdue",E2-TODAY()),"")) -> Closed | M7: =IF(G2="Closed","✓",IF(G2="Delayed","⚠ DELAYED",IF(AND(E2<>"",E2<TODAY()),"⛔ OVERDUE",IF(AND(E2<>"",E2-TODAY()<=7),"⏰ Due Soon","")))) -> ✓
A8: 7 | B8: البدء في تصميم نظام إجراءات نزلاء السجون (UI/UX & Story Board for MVP Services) | C8: الأنتهاء من إعداد وثيقة تصميم الحل لخدمات MVP | D8: Moataz Alfarajah | E8: 46037 | F8: - | G8: Closed | H8: - | I8: 46068 | J8: +31 | L8: =IF(G2="Closed","Closed",IF(E2<>"",IF(E2<TODAY(),"Overdue",E2-TODAY()),"")) -> Closed | M8: =IF(G2="Closed","✓",IF(G2="Delayed","⚠ DELAYED",IF(AND(E2<>"",E2<TODAY()),"⛔ OVERDUE",IF(AND(E2<>"",E2-TODAY()<=7),"⏰ Due Soon","")))) -> ✓
A9: 8 | B9: أستكمال جمع المتطلبات الغير وظيفية لجميع الخدمات | C9: الأجتماع مع المعنيين في الأدارات من المديرية وتزويد الشركة بالحقول والنماذج لجميع الخدمات | D9: Muath Albkr & PGD | E9: 46037 | F9: 46080 | G9: Closed | H9: - | I9: 46078 | L9: =IF(G2="Closed","Closed",IF(E2<>"",IF(E2<TODAY(),"Overdue",E2-TODAY()),"")) -> Closed | M9: =IF(G2="Closed","✓",IF(G2="Delayed","⚠ DELAYED",IF(AND(E2<>"",E2<TODAY()),"⛔ OVERDUE",IF(AND(E2<>"",E2-TODAY()<=7),"⏰ Due Soon","")))) -> ✓
A10: 9 | B10: تسليم وثيقة متطلبات الأعمال التفصيلية SRS لجميع الخدمات (full scope) | C10: أستكمال جمع المتطلبات الغير وظيفية لجميع الخدمات | D10: Mohammed Aledi | E10: 46041 | G10: Closed | I10: 46106 | L10: =IF(G2="Closed","Closed",IF(E2<>"",IF(E2<TODAY(),"Overdue",E2-TODAY()),"")) -> Closed | M10: =IF(G2="Closed","✓",IF(G2="Delayed","⚠ DELAYED",IF(AND(E2<>"",E2<TODAY()),"⛔ OVERDUE",IF(AND(E2<>"",E2-TODAY()<=7),"⏰ Due Soon","")))) -> ✓
A11: 10 | B11: البدء في إعداد وثيقة تصميم الحل لجميع الخدمات (full scope) | C11: أعتماد وثيقة متطلبات الأعمال التفصيلية SRS لجميع الخدمات | D11: Muath Albkr | E11: 46078 | G11: Closed | I11: 46078 | L11: =IF(G2="Closed","Closed",IF(E2<>"",IF(E2<TODAY(),"Overdue",E2-TODAY()),"")) -> Closed | M11: =IF(G2="Closed","✓",IF(G2="Delayed","⚠ DELAYED",IF(AND(E2<>"",E2<TODAY()),"⛔ OVERDUE",IF(AND(E2<>"",E2-TODAY()<=7),"⏰ Due Soon","")))) -> ✓
A12: 11 | B12: البدء في تصميم نظام إجراءات نزلاء السجون (UI/UX & Story Board for Full Scope) | C12: الأنتهاء من إعداد وثيقة تصميم الحل لجميع الخدمات (full scope) | D12: Moataz Alfarajah | E12: 46092 | G12: Closed | I12: 46112 | L12: =IF(G2="Closed","Closed",IF(E2<>"",IF(E2<TODAY(),"Overdue",E2-TODAY()),"")) -> Closed | M12: =IF(G2="Closed","✓",IF(G2="Delayed","⚠ DELAYED",IF(AND(E2<>"",E2<TODAY()),"⛔ OVERDUE",IF(AND(E2<>"",E2-TODAY()<=7),"⏰ Due Soon","")))) -> ✓
A13: 12 | B13: البدء بتطوير نظام إجراءات نزلاء السجون (MVP) | C13: أعتماد تصميم نظام إجراءات نزلاء السجون (UI/UX & Story Board for MVP Services) | D13: Muath Albkr | E13: 46042 | F13: 46079 | G13: Closed | H13: - | I13: 46082 | L13: =IF(G2="Closed","Closed",IF(E2<>"",IF(E2<TODAY(),"Overdue",E2-TODAY()),"")) -> Closed | M13: =IF(G2="Closed","✓",IF(G2="Delayed","⚠ DELAYED",IF(AND(E2<>"",E2<TODAY()),"⛔ OVERDUE",IF(AND(E2<>"",E2-TODAY()<=7),"⏰ Due Soon","")))) -> ✓
A14: 13 | B14: البدء بتطوير نظام إجراءات نزلاء السجون (Full Scope) | C14: أعتماد تصميم نظام إجراءات نزلاء السجون (UI/UX & Story Board for Full Scope) | D14: Muath Albkr | E14: 46091 | F14: 46079 | G14: Delayed | H14: - | L14: =IF(G2="Closed","Closed",IF(E2<>"",IF(E2<TODAY(),"Overdue",E2-TODAY()),"")) -> Closed | M14: =IF(G2="Closed","✓",IF(G2="Delayed","⚠ DELAYED",IF(AND(E2<>"",E2<TODAY()),"⛔ OVERDUE",IF(AND(E2<>"",E2-TODAY()<=7),"⏰ Due Soon","")))) -> ✓
A15: 14 | B15: البدء من اختبارات المرحلة الأولى وقبول المستخدم (MVP) | C15: الأنتهاء من تطوير نظام إجراءات نزلاء السجون (MVP) | D15: Tawah Alsindi | E15: 46078 | F15: 46096 | G15: Closed | I15: 46094 | L15: =IF(G2="Closed","Closed",IF(E2<>"",IF(E2<TODAY(),"Overdue",E2-TODAY()),"")) -> Closed | M15: =IF(G2="Closed","✓",IF(G2="Delayed","⚠ DELAYED",IF(AND(E2<>"",E2<TODAY()),"⛔ OVERDUE",IF(AND(E2<>"",E2-TODAY()<=7),"⏰ Due Soon","")))) -> ✓
A16: 15 | B16: الانتهاء من اختبارات المرحلة الثانية وقبول المستخدم (Full Scope) | C16: الأنتهاء من تطوير نظام إجراءات نزلاء السجون (Full Scope) | D16: Tawah Alsindi | E16: 46321 | L16: =IF(G2="Closed","Closed",IF(E2<>"",IF(E2<TODAY(),"Overdue",E2-TODAY()),"")) -> Closed | M16: =IF(G2="Closed","✓",IF(G2="Delayed","⚠ DELAYED",IF(AND(E2<>"",E2<TODAY()),"⛔ OVERDUE",IF(AND(E2<>"",E2-TODAY()<=7),"⏰ Due Soon","")))) -> ✓
A17: 16 | B17: البدء في إختبارات أداء النظام والفحص الامني/الإختراق (كامل النظام) | C17: الانتهاء من اختبارات المرحلة الثانية وقبول المستخدم (Full Scope) | D17: Tawah Alsindi | E17: 46363 | L17: =IF(G2="Closed","Closed",IF(E2<>"",IF(E2<TODAY(),"Overdue",E2-TODAY()),"")) -> Closed | M17: =IF(G2="Closed","✓",IF(G2="Delayed","⚠ DELAYED",IF(AND(E2<>"",E2<TODAY()),"⛔ OVERDUE",IF(AND(E2<>"",E2-TODAY()<=7),"⏰ Due Soon","")))) -> ✓
A18: 17 | B18: إطلاق نظام إجراءات نزلاء السجون (MVP) | C18: الانتهاء من إختبارات أداء النظام والفحص الامني/الإختراق (كامل النظام) , والنشر على البيئة التشغيلية | D18: Tawah Alsindi | E18: 46383 | L18: =IF(G2="Closed","Closed",IF(E2<>"",IF(E2<TODAY(),"Overdue",E2-TODAY()),"")) -> Closed | M18: =IF(G2="Closed","✓",IF(G2="Delayed","⚠ DELAYED",IF(AND(E2<>"",E2<TODAY()),"⛔ OVERDUE",IF(AND(E2<>"",E2-TODAY()<=7),"⏰ Due Soon","")))) -> ✓
A19: 18 | B19: إطلاق نظام إجراءات نزلاء السجون (Full Scope + Dashboard) | C19: الانتهاء من إختبارات أداء النظام والفحص الامني/الإختراق (كامل النظام) , والنشر على البيئة التشغيلية | D19: Tawah Alsindi | E19: 46383 | L19: =IF(G2="Closed","Closed",IF(E2<>"",IF(E2<TODAY(),"Overdue",E2-TODAY()),"")) -> Closed | M19: =IF(G2="Closed","✓",IF(G2="Delayed","⚠ DELAYED",IF(AND(E2<>"",E2<TODAY()),"⛔ OVERDUE",IF(AND(E2<>"",E2-TODAY()<=7),"⏰ Due Soon","")))) -> ✓
A20: 19 | B20: الانتهاء من إطلاق نظام عرض البيانات* | C20: - | D20: Muath Albkr | E20: 46387 | L20: =IF(G2="Closed","Closed",IF(E2<>"",IF(E2<TODAY(),"Overdue",E2-TODAY()),"")) -> Closed | M20: =IF(G2="Closed","✓",IF(G2="Delayed","⚠ DELAYED",IF(AND(E2<>"",E2<TODAY()),"⛔ OVERDUE",IF(AND(E2<>"",E2-TODAY()<=7),"⏰ Due Soon","")))) -> ✓
A21: 20 | B21: الدعم الفني والتشغيل | C21: إطلاق نظام إجراءات نزلاء السجون (كامل النظام) | D21: Tawah Alsindi | E21: 46387 | L21: =IF(G2="Closed","Closed",IF(E2<>"",IF(E2<TODAY(),"Overdue",E2-TODAY()),"")) -> Closed | M21: =IF(G2="Closed","✓",IF(G2="Delayed","⚠ DELAYED",IF(AND(E2<>"",E2<TODAY()),"⛔ OVERDUE",IF(AND(E2<>"",E2-TODAY()<=7),"⏰ Due Soon","")))) -> ✓
A22: 21 | B22: نقل المعرفة وتسليم وثائق المشروع | C22: الأنتهاء من إطلاق نظام إجراءات نزلاء السجون (كامل النظام) | D22: Tawah Alsindi | E22: 46387 | L22: =IF(G2="Closed","Closed",IF(E2<>"",IF(E2<TODAY(),"Overdue",E2-TODAY()),"")) -> Closed | M22: =IF(G2="Closed","✓",IF(G2="Delayed","⚠ DELAYED",IF(AND(E2<>"",E2<TODAY()),"⛔ OVERDUE",IF(AND(E2<>"",E2-TODAY()<=7),"⏰ Due Soon","")))) -> ✓
A23: 22 | L23: =IF(G2="Closed","Closed",IF(E2<>"",IF(E2<TODAY(),"Overdue",E2-TODAY()),"")) -> Closed | M23: =IF(G2="Closed","✓",IF(G2="Delayed","⚠ DELAYED",IF(AND(E2<>"",E2<TODAY()),"⛔ OVERDUE",IF(AND(E2<>"",E2-TODAY()<=7),"⏰ Due Soon","")))) -> ✓
A24: 23 | L24: =IF(G2="Closed","Closed",IF(E2<>"",IF(E2<TODAY(),"Overdue",E2-TODAY()),"")) -> Closed | M24: =IF(G2="Closed","✓",IF(G2="Delayed","⚠ DELAYED",IF(AND(E2<>"",E2<TODAY()),"⛔ OVERDUE",IF(AND(E2<>"",E2-TODAY()<=7),"⏰ Due Soon","")))) -> ✓
A25: 24 | L25: =IF(G2="Closed","Closed",IF(E2<>"",IF(E2<TODAY(),"Overdue",E2-TODAY()),"")) -> Closed | M25: =IF(G2="Closed","✓",IF(G2="Delayed","⚠ DELAYED",IF(AND(E2<>"",E2<TODAY()),"⛔ OVERDUE",IF(AND(E2<>"",E2-TODAY()<=7),"⏰ Due Soon","")))) -> ✓
A26: 25 | L26: =IF(G2="Closed","Closed",IF(E2<>"",IF(E2<TODAY(),"Overdue",E2-TODAY()),"")) -> Closed | M26: =IF(G2="Closed","✓",IF(G2="Delayed","⚠ DELAYED",IF(AND(E2<>"",E2<TODAY()),"⛔ OVERDUE",IF(AND(E2<>"",E2-TODAY()<=7),"⏰ Due Soon","")))) -> ✓

Sheet Risks
A1: # | B1: Risk Title | C1: Responsibility | D1: Raised Date | E1: Impact Description | F1: Status | G1: Priority | H1: Impact | I1: Probability | J1: Mitigation Plan | K1: Mitigation Owner | L1: History Comments | M1: Closure Due Date | N1: Revised Closure Due Date | O1: Actual Closure Date | P1: Risk Score | Q1: Risk Level | R1: Days Open
A2: R-001 | B2: تأخر تحديد واعتماد خدمات المرحلة الأولى MVP | C2: Muath Albkr | D2: 46028 | E2: تأخير مصادقة متطلبات وثيقة متطلبات الأعمال وعقد ورش العمل اللازمة مع المديرية. | F2: Inactive | G2: Critical | H2: High | I2: Medium | J2: الاستعجال في عقد ورش نقل المعرفة بالتنسيق مع شركة يونيكوم لضمان إغلاق مرحلة التحليل في الوقت المحدد. | K2: Muath Albkr | L2: 7 يناير: تم تصعيد تأثير تأخر جلسات نقل المعرفة على بدء تحديد وتحليل خدمات الـ MVP وإغلاق مرحلة التحليل. | M2: 46027 | O2: 46037 | P2: {=IF(OR(B2="",F2="Inactive"),"",IF(AND(H2<>"",I2<>""),(_xlfn.SWITCH(H2,"Critical",4,"High",3,"Medium",2,"Low",1,0))*(_xlfn.SWITCH(I2,"High",3,"Highly Probable",3,"Medium",2,"Probable",2,"Low",1,"Less Likely",1,0)),""))} | Q2: =IF(P2="","",IF(P2>=9,"CRITICAL",IF(P2>=6,"HIGH",IF(P2>=3,"MEDIUM","LOW")))) | R2: =IF(AND(D2<>"",OR(F2="Active",F2="Escalated to Issue")),TODAY()-D2,"")
A3: R-002 | B3: عدم جاهزية بيئات العمل التطويرية ، الأختبارية والتشغيلية وعدم توفير المتطلبات الأساسية الأخرى مثل المنافذ والشبكة وجدار الحماية وحسابات الخدمة | C3: Muath Albkr & PGD | D3: 46034 | E3: تأخير البدء في أنشطة التطوير والتنفيذ | F3: Inactive | G3: High | H3: High | I3: High | J3: توفير صلاحيات الوصول المطلوبة والتأكد من جاهزية الخوادم، مع تخصيص مهندس من الشركة للعمل بشكل مباشر مع فريق البنية التحتية للمديرية لتسريع تجهيز البيئات ومعالجة أي معوقات تقنية | K3: Muath Albkr | L3: 20 يناير: تم تصعيد ضرورة توفير الصلاحيات وعقد اجتماع مع الفريق التقني في المديرية. 01 فبراير: تم توفير مهندس من قبل الشركة للعمل المباشر مع فريق البنية التحتية وتسريع تجهيز البيئات 02 مارس: تم البدء بتطوير خدمات الـ MVP 31 مارس: عقد جلسة عرض توضيحي لخدمة الشكاوى مع فريق المديرية وسامي 13 أبريل: تم اكتمال تطوير البوابة وجهاز الخدمة الذاتية لخدمات المرحلة الأولى (MVP) ، مع انتظار جاهزية التكامل من طرف المديرية ومشاركتها مع فريق الشركة 19 أبريل: عقد جلسة عرض توضيحي لخدمات MVP مع فريق المديرية وسامي ومشاركة بعض التعديلات للشركة لتنفيذها | M3: 46042 | O3: 46083 | P3: {=IF(OR(B2="",F2="Inactive"),"",IF(AND(H2<>"",I2<>""),(_xlfn.SWITCH(H2,"Critical",4,"High",3,"Medium",2,"Low",1,0))*(_xlfn.SWITCH(I2,"High",3,"Highly Probable",3,"Medium",2,"Probable",2,"Low",1,"Less Likely",1,0)),""))} | Q3: =IF(P2="","",IF(P2>=9,"CRITICAL",IF(P2>=6,"HIGH",IF(P2>=3,"MEDIUM","LOW")))) | R3: =IF(AND(D2<>"",OR(F2="Active",F2="Escalated to Issue")),TODAY()-D2,"")
A4: R-003 | B4: وجود خدمات جديدة غير معتمدة وغير مدرجة ضمن نطاق المشروع | C4: Muath Albkr | D4: 46036 | E4: توسع غير مخطط في نطاق المشروع وتأخير إغلاق المشروع حسب الخطة المعتمدة. | F4: Inactive | G4: Critical | H4: High | I4: Medium | J4: الالتزام بنطاق المشروع المعتمد، وتقييم أثر أي طلبات جديدة وعرضها على اللجان المشتركة لاتخاذ القرار. | K4: Muath Albkr | M4: 46027 | O4: 46037 | P4: {=IF(OR(B2="",F2="Inactive"),"",IF(AND(H2<>"",I2<>""),(_xlfn.SWITCH(H2,"Critical",4,"High",3,"Medium",2,"Low",1,0))*(_xlfn.SWITCH(I2,"High",3,"Highly Probable",3,"Medium",2,"Probable",2,"Low",1,"Less Likely",1,0)),""))} | Q4: =IF(P2="","",IF(P2>=9,"CRITICAL",IF(P2>=6,"HIGH",IF(P2>=3,"MEDIUM","LOW")))) | R4: =IF(AND(D2<>"",OR(F2="Active",F2="Escalated to Issue")),TODAY()-D2,"")
A5: R-004 | B5: تأخر بدء أنشطة التصميم والتطوير للمرحلة الأولى MVP | C5: PGD | D5: 46042 | E5: ضغط الجدول الزمني وتأخير تسليم خدمات الـ MVP. | F5: Inactive | G5: Critical | H5: Critical | I5: High | J5: بدء التصميم والتطوير بشكل متواز حيثما أمكن وبشكل عاجل لتقليل الأثر الزمني. تصعيد أي تأخير في الاعتمادات خلال 48 ساعة إلى اللجنة التوجيهية لاتخاذ القرار | K5: Tawah Alsindi | L5: 20 يناير: مناقشة تأخر مشاركة الحقول والنماذج وتأثيره على الجدول الزمني خلال الاجتماع الأسبوعي مع فريق سامي. 25 يناير: عقد اجتماع مع المساعد للعمليات لمناقشة تسليم النماذج وبيانات الـ Metadata وطلبات تعديل مسارات الإجراءات المعتمدة. 2 فبراير: اجتماع مع فريق المديرية لمناقشة التحديات والتأكيد على ضرورة مشاركة النماذج والحقول لخدمات الـ MVP. 3 فبراير: تم مشاركة واعتماد حقول خدمة الشكاوى والاقتراحات. 15 فبراير: تم البدء بتصميم واجهات النطام لخدمة الشكاوي والأقتراحات 01 مارس: تم أعتماد التصمايم والبدء بالتطوير | M5: 46037 | O5: 46082 | P5: {=IF(OR(B2="",F2="Inactive"),"",IF(AND(H2<>"",I2<>""),(_xlfn.SWITCH(H2,"Critical",4,"High",3,"Medium",2,"Low",1,0))*(_xlfn.SWITCH(I2,"High",3,"Highly Probable",3,"Medium",2,"Probable",2,"Low",1,"Less Likely",1,0)),""))} | Q5: =IF(P2="","",IF(P2>=9,"CRITICAL",IF(P2>=6,"HIGH",IF(P2>=3,"MEDIUM","LOW")))) | R5: =IF(AND(D2<>"",OR(F2="Active",F2="Escalated to Issue")),TODAY()-D2,"")
A6: R-005 | B6: عدم توفر أصحاب المصلحة من المديرية | C6: PGD | D6: 46049 | E6: تأخير استكمال المتطلبات غير الوظيفية وتسليم وثيقة متطلبات النظام (SRS). | F6: Inactive | G6: Critical | H6: Critical | I6: High | J6: تفعيل آلية تواصل فعالة من خلال عقد اجتماعات يومية مع فريق المديرية والإدارات ذات العلاقة لاستكمال المتطلبات المتبقية، مع متابعة التقدم والمعوقات ضمن الاجتماع الأسبوعي | K6: Muath Albkr | L6: 2 فبراير: عقد اجتماع مع فريق المديرية لمناقشة التحديات والتأكيد على آلية الاجتماع اليومي لاستكمال المتطلبات المتبقية | M6: 46027 | P6: {=IF(OR(B2="",F2="Inactive"),"",IF(AND(H2<>"",I2<>""),(_xlfn.SWITCH(H2,"Critical",4,"High",3,"Medium",2,"Low",1,0))*(_xlfn.SWITCH(I2,"High",3,"Highly Probable",3,"Medium",2,"Probable",2,"Low",1,"Less Likely",1,0)),""))} | Q6: =IF(P2="","",IF(P2>=9,"CRITICAL",IF(P2>=6,"HIGH",IF(P2>=3,"MEDIUM","LOW")))) | R6: =IF(AND(D2<>"",OR(F2="Active",F2="Escalated to Issue")),TODAY()-D2,"")
A7: R-006 | B7: عدم استكمال واعتماد المتطلبات غير الوظيفية لخدمات MVP | C7: PGD | D7: 46036 | E7: تأخير إغلاق مرحلة التحليل مما أدى إلى تأخير بدء التصميم والتطوير للمرحلة الأولى | F7: Inactive | G7: Critical | H7: Critical | I7: High | J7: مشاركة ملف تصنيف الخدمات والإدارات التابعة لها مع المديرية لتنسيق عقد الاجتماعات اللازمة واستكمال واعتماد المتطلبات غير الوظيفية خلال الفترة المحددة | K7: Muath Albkr | L7: 20 يناير: تمت مناقشة التأخير في مشاركة الحقول و والنماذج المتعلقة بالخدمات من قبل المديرية في الأجتماع الأسبوعي مع فريق سامي لأتخاذ الأجراء والأجتماع مع الأدارات لأنهاء الخدمات الوظيفية 20 يناير: تمت مناقشة التأخير في مشاركة الحقول و والنماذج والتأخير المترتب على الجدول الزمني للبدء في اعداد وثيقة متطلبات الأعمال التفصيلية و تسليم خدمات MVP 25 يناير: تم عقد اجتماع مع المساعد للعمليات، ومناقشة تسليم النماذج وال Metadata المطلوبة لخدمات MVP ومناقشة طلبات لتعديل مسارات الإجراءات التي تم اعتمادها والموافقة عليها مسبقًا خلال مرحلة التحليل 2 فبراير: تم الأجتماع مع فريق المديرية د. نمر ومناقشة التحديات وضرورة مشاركة النماذج والحقول لخدمات MVP 3 فبراير: تم مشاركة وأعتماد حقول خدمة الشكاوي والأقتراحات 10 فبراير: تم مناقشة التأخير على أعتماد التعديلات على خدمة النقل والخروج للضروره مع فريق المديرية وضرورة الحصول على الأعتماد بشكل عاجل اليوم، لم يتمكن فريق التنفيذ من الحصول على الأعتماد بسبب عدم تواجد إدارة مساعد العمليات 15 قبراير: تم الأجتماع مع فريق المديرية و الأتفاق على البدء بتنفيذ نطاق MVP ، ويشمل ذلك الخدمات بناًء على المعلومات المتاحة حاليا التالية: الشكاوي واالقتراحات – النقل – طلب الخروج 12 مارس: تمت مشاركة وثيقة متطلبات الأعمال ل 8 خدمات | M7: 46027 | O7: 46068 | P7: {=IF(OR(B2="",F2="Inactive"),"",IF(AND(H2<>"",I2<>""),(_xlfn.SWITCH(H2,"Critical",4,"High",3,"Medium",2,"Low",1,0))*(_xlfn.SWITCH(I2,"High",3,"Highly Probable",3,"Medium",2,"Probable",2,"Low",1,"Less Likely",1,0)),""))} | Q7: =IF(P2="","",IF(P2>=9,"CRITICAL",IF(P2>=6,"HIGH",IF(P2>=3,"MEDIUM","LOW")))) | R7: =IF(AND(D2<>"",OR(F2="Active",F2="Escalated to Issue")),TODAY()-D2,"")
A8: R-007 | B8: عدم الالتزام بالجدول الزمني المعتمد | C8: Muath Albkr & PGD | D8: 46056 | E8: تراكم التأخيرات وتأثير على الجدول الزمني لإغلاق خدمات المرحلة الأولى وخدمات الأطلاق الكامل للنظام | F8: Escalated to Issue | G8: Critical | H8: High | I8: High | J8: المتابعة الدورية مع أصحاب المصلحة والتصعيد المبكر لأي تأخير مؤثر، مع تنفيذ بعض أنشطة المشروع بشكل متواز لتسريع الإنجاز | K8: Muath Albkr | L8: 2 فبراير: تمت مناقشة الأثر التراكمي للتأخيرات الناتجة عن تأخر استكمال المتطلبات غير الوظيفية على الجدول الزمني المعتمد. | M8: 46023 | P8: {=IF(OR(B2="",F2="Inactive"),"",IF(AND(H2<>"",I2<>""),(_xlfn.SWITCH(H2,"Critical",4,"High",3,"Medium",2,"Low",1,0))*(_xlfn.SWITCH(I2,"High",3,"Highly Probable",3,"Medium",2,"Probable",2,"Low",1,"Less Likely",1,0)),""))} | Q8: =IF(P2="","",IF(P2>=9,"CRITICAL",IF(P2>=6,"HIGH",IF(P2>=3,"MEDIUM","LOW")))) | R8: =IF(AND(D2<>"",OR(F2="Active",F2="Escalated to Issue")),TODAY()-D2,"")
A9: R-008 | B9: عدم جاهزية مرحلة التحليل لخدمتي (البيت العائلي والأمانات)، وذلك لعدم تأكيدها واعتمادها في المرحلة السابقة مع فريق شركة يونيكوم | C9: Muath Albkr & PGD | D9: 46042 | E9: تأخير تحليل وتسليم التحليل الفني والتقني للخدمتين | F9: Active | G9: High | H9: High | I9: Medium | J9: عقد الأجتماعات مع الأدارات المعنية والتأكيد على المتطلبات التقنية والفنية والحصول على تأكيد رسمي من المديرية بشأن إدراج أو استبعاد خدمة الأمانات من النطاق. | K9: Muath Albkr | L9: خلال جلسات التسليم مع فريق Unickomm Platformation، أفاد الفريق بأن المتطلبات النهائية لهاتين الخدمتين لم يتم توفيرها فيما يخص خدمة «الأمانات»، تمت مناقشة التفاصيل مع PGD، حيث أفادونا بضرورة وضع الخدمة قيد الإيقاف مؤقتًا، نظرًا لوجود نظام آخر وهو «Nazeel Pay» مخصص لخدمة «الأمانات»، ويرغبون أولًا في التحقق واعتماد هذا التوجه فيما يخص خدمة «البيت العائلي»، سيتم مناقشة المتطلبات النهائية مع الجهة المختصة خلال جلسات المتطلبات غير الوظيفية، حيث إنها غير جاهزة حاليًا. كما أوصت PGD بجدولة هذه المناقشة لتكون الاجتماع الأخير 26 فبراير: تم التأكيد من قبل المديرية بأنه يتم تطوير عمل الخدمة مقتصراً على الأمانات العينية فقط 08 مارس: عقد أجتماع مع فريق المديرية لخدمة البيت العائلي حيث تم مشاركة الملفات الخاصة بخدمة البيت العائلي وانتظار المراجعة مع الادارة المعنية (مسار العمل) | M9: 46063 | P9: {=IF(OR(B2="",F2="Inactive"),"",IF(AND(H2<>"",I2<>""),(_xlfn.SWITCH(H2,"Critical",4,"High",3,"Medium",2,"Low",1,0))*(_xlfn.SWITCH(I2,"High",3,"Highly Probable",3,"Medium",2,"Probable",2,"Low",1,"Less Likely",1,0)),""))} | Q9: =IF(P2="","",IF(P2>=9,"CRITICAL",IF(P2>=6,"HIGH",IF(P2>=3,"MEDIUM","LOW")))) | R9: =IF(AND(D2<>"",OR(F2="Active",F2="Escalated to Issue")),TODAY()-D2,"")
A10: R-010 | B10: عدم تأكيد اعتماد تطوير تطبيق جوال ضمن نطاق المشروع أو الاكتفاء بالبوابة المتجاوبة. | C10: Muath Albkr & PGD | D10: 46029 | E10: على الرغم من ورود متطلبات تطبيق الهاتف المحمول ضمن نطاق المشروع، إلا أنه لم يتم حتى الان تأكيد ما إذا كان سيتم اعتماد تطوير تطبيق جوال مستقل أو الاكتفاء باستخدام البوابة عبر الهاتف بتصميم متجاوب، وذلك في ظل كون المشروع حاليًا في مرحلة التحليل والذي قد يؤدي إلى اختلاف جوهري في نطاق العمل، إعادة التحليل والتصميم، وتأخير بدء أنشطة التطوير، مع تأثير مباشر على الجدول الزمني | F10: Active | G10: High | H10: High | I10: Medium | J10: طلب قرار رسمي ومعتمد من المديرية لتأكيد اعتماد تطوير تطبيق الجوال أو الاكتفاء باستخدام البوابة المتجاوبة | K10: Muath Albkr | L10: 3 فبراير: خلال الاجتماع الأسبوعي وعدة أجتماعات سابقه وبحضور فريق المديرية، تم التوضيح بأن الخدمة مدرجة حاليًا ضمن نطاق مشروع ، ولم يتم حتى تاريخه تأكيد ما إذا كان سيتم اعتماد تطوير تطبيق جوال ضمن نطاق المشروع أو الاكتفاء بالبوابة المتجاوبة | M10: 46063 | P10: {=IF(OR(B2="",F2="Inactive"),"",IF(AND(H2<>"",I2<>""),(_xlfn.SWITCH(H2,"Critical",4,"High",3,"Medium",2,"Low",1,0))*(_xlfn.SWITCH(I2,"High",3,"Highly Probable",3,"Medium",2,"Probable",2,"Low",1,"Less Likely",1,0)),""))} | Q10: =IF(P2="","",IF(P2>=9,"CRITICAL",IF(P2>=6,"HIGH",IF(P2>=3,"MEDIUM","LOW")))) | R10: =IF(AND(D2<>"",OR(F2="Active",F2="Escalated to Issue")),TODAY()-D2,"")
A11: R-011 | B11: تكرار التعديلات على سير العمل لخدمة طلب النقل والخروج للضرورة "وثيقة متطلبات الأعمال معتمدة" | C11: Marwan | D11: 46062 | E11: إعادة العمل على التحليل وسير العمل تأخير البدء في التصميم و التطوير التأثير على الجدول الزمني المعتمد للمشروع | F11: Inactive | G11: Critical | H11: High | I11: High | J11: اعتماد تنفيذ أي تعديلات على سير العمل فقط من خلال آلية إدارة التغيير المعتمدة, وربط أي تعديل بتقييم أثر معتمد يوضح تأثيره على النطاق والجدول الزمني والجهد قبل التنفيذ. عقد أجتماع مع المديرية لأعتماد سير العمل النهائي قبل البدء بالتطوير | K11: Muath Albkr | L11: 9 فبراير: بعد استلام النماذج والحقول الخاصة بخدمتي طلب النقل وطلب الخروج للضرورة، وردت عدة ملاحظات تتطلب تعديل سير العمل؛ حيث تم طلب تعديل المسار في المرحلة الأولى، تلاه لاحقًا طلب تقسيم سير العمل إلى مسارين مختلفين، مع الاستمرار في إضافة ملاحظات جديدة للتعديل، وذلك على الرغم من أن وثيقة متطلبات الأعمال (BRD) معتمدة مسبقًا من قبل شركة يونيكوم 15 فبراير: تم أعتماد النماذج والحقول لخدمات MVP | M11: 46064 | O11: 46068 | P11: {=IF(OR(B2="",F2="Inactive"),"",IF(AND(H2<>"",I2<>""),(_xlfn.SWITCH(H2,"Critical",4,"High",3,"Medium",2,"Low",1,0))*(_xlfn.SWITCH(I2,"High",3,"Highly Probable",3,"Medium",2,"Probable",2,"Low",1,"Less Likely",1,0)),""))} | Q11: =IF(P2="","",IF(P2>=9,"CRITICAL",IF(P2>=6,"HIGH",IF(P2>=3,"MEDIUM","LOW")))) | R11: =IF(AND(D2<>"",OR(F2="Active",F2="Escalated to Issue")),TODAY()-D2,"")
A12: R-012 | B12: إجراء تعديلات على سير الأعمال المعتمدة بعد تطويرها. | C12: Muath Albkr & PGD | D12: 46133 | P12: {=IF(OR(B2="",F2="Inactive"),"",IF(AND(H2<>"",I2<>""),(_xlfn.SWITCH(H2,"Critical",4,"High",3,"Medium",2,"Low",1,0))*(_xlfn.SWITCH(I2,"High",3,"Highly Probable",3,"Medium",2,"Probable",2,"Low",1,"Less Likely",1,0)),""))} | Q12: =IF(P2="","",IF(P2>=9,"CRITICAL",IF(P2>=6,"HIGH",IF(P2>=3,"MEDIUM","LOW")))) | R12: =IF(AND(D2<>"",OR(F2="Active",F2="Escalated to Issue")),TODAY()-D2,"")
A13: R-013 | P13: {=IF(OR(B2="",F2="Inactive"),"",IF(AND(H2<>"",I2<>""),(_xlfn.SWITCH(H2,"Critical",4,"High",3,"Medium",2,"Low",1,0))*(_xlfn.SWITCH(I2,"High",3,"Highly Probable",3,"Medium",2,"Probable",2,"Low",1,"Less Likely",1,0)),""))} | Q13: =IF(P2="","",IF(P2>=9,"CRITICAL",IF(P2>=6,"HIGH",IF(P2>=3,"MEDIUM","LOW")))) | R13: =IF(AND(D2<>"",OR(F2="Active",F2="Escalated to Issue")),TODAY()-D2,"")
A14: R-013 | P14: {=IF(OR(B2="",F2="Inactive"),"",IF(AND(H2<>"",I2<>""),(_xlfn.SWITCH(H2,"Critical",4,"High",3,"Medium",2,"Low",1,0))*(_xlfn.SWITCH(I2,"High",3,"Highly Probable",3,"Medium",2,"Probable",2,"Low",1,"Less Likely",1,0)),""))} | Q14: =IF(P2="","",IF(P2>=9,"CRITICAL",IF(P2>=6,"HIGH",IF(P2>=3,"MEDIUM","LOW")))) | R14: =IF(AND(D2<>"",OR(F2="Active",F2="Escalated to Issue")),TODAY()-D2,"")
A15: R-014 | P15: {=IF(OR(B2="",F2="Inactive"),"",IF(AND(H2<>"",I2<>""),(_xlfn.SWITCH(H2,"Critical",4,"High",3,"Medium",2,"Low",1,0))*(_xlfn.SWITCH(I2,"High",3,"Highly Probable",3,"Medium",2,"Probable",2,"Low",1,"Less Likely",1,0)),""))} | Q15: =IF(P2="","",IF(P2>=9,"CRITICAL",IF(P2>=6,"HIGH",IF(P2>=3,"MEDIUM","LOW")))) | R15: =IF(AND(D2<>"",OR(F2="Active",F2="Escalated to Issue")),TODAY()-D2,"")
A16: R-017 | P16: {=IF(OR(B2="",F2="Inactive"),"",IF(AND(H2<>"",I2<>""),(_xlfn.SWITCH(H2,"Critical",4,"High",3,"Medium",2,"Low",1,0))*(_xlfn.SWITCH(I2,"High",3,"Highly Probable",3,"Medium",2,"Probable",2,"Low",1,"Less Likely",1,0)),""))} | Q16: =IF(P2="","",IF(P2>=9,"CRITICAL",IF(P2>=6,"HIGH",IF(P2>=3,"MEDIUM","LOW")))) | R16: =IF(AND(D2<>"",OR(F2="Active",F2="Escalated to Issue")),TODAY()-D2,"")
A17: R-018 | P17: {=IF(OR(B2="",F2="Inactive"),"",IF(AND(H2<>"",I2<>""),(_xlfn.SWITCH(H2,"Critical",4,"High",3,"Medium",2,"Low",1,0))*(_xlfn.SWITCH(I2,"High",3,"Highly Probable",3,"Medium",2,"Probable",2,"Low",1,"Less Likely",1,0)),""))} | Q17: =IF(P2="","",IF(P2>=9,"CRITICAL",IF(P2>=6,"HIGH",IF(P2>=3,"MEDIUM","LOW")))) | R17: =IF(AND(D2<>"",OR(F2="Active",F2="Escalated to Issue")),TODAY()-D2,"")
A18: R-019 | P18: {=IF(OR(B2="",F2="Inactive"),"",IF(AND(H2<>"",I2<>""),(_xlfn.SWITCH(H2,"Critical",4,"High",3,"Medium",2,"Low",1,0))*(_xlfn.SWITCH(I2,"High",3,"Highly Probable",3,"Medium",2,"Probable",2,"Low",1,"Less Likely",1,0)),""))} | Q18: =IF(P2="","",IF(P2>=9,"CRITICAL",IF(P2>=6,"HIGH",IF(P2>=3,"MEDIUM","LOW")))) | R18: =IF(AND(D2<>"",OR(F2="Active",F2="Escalated to Issue")),TODAY()-D2,"")
A19: R-020 | P19: {=IF(OR(B2="",F2="Inactive"),"",IF(AND(H2<>"",I2<>""),(_xlfn.SWITCH(H2,"Critical",4,"High",3,"Medium",2,"Low",1,0))*(_xlfn.SWITCH(I2,"High",3,"Highly Probable",3,"Medium",2,"Probable",2,"Low",1,"Less Likely",1,0)),""))} | Q19: =IF(P2="","",IF(P2>=9,"CRITICAL",IF(P2>=6,"HIGH",IF(P2>=3,"MEDIUM","LOW")))) | R19: =IF(AND(D2<>"",OR(F2="Active",F2="Escalated to Issue")),TODAY()-D2,"")
A20: R-021 | P20: {=IF(OR(B2="",F2="Inactive"),"",IF(AND(H2<>"",I2<>""),(_xlfn.SWITCH(H2,"Critical",4,"High",3,"Medium",2,"Low",1,0))*(_xlfn.SWITCH(I2,"High",3,"Highly Probable",3,"Medium",2,"Probable",2,"Low",1,"Less Likely",1,0)),""))} | Q20: =IF(P2="","",IF(P2>=9,"CRITICAL",IF(P2>=6,"HIGH",IF(P2>=3,"MEDIUM","LOW")))) | R20: =IF(AND(D2<>"",OR(F2="Active",F2="Escalated to Issue")),TODAY()-D2,"")
A21: R-022 | P21: {=IF(OR(B2="",F2="Inactive"),"",IF(AND(H2<>"",I2<>""),(_xlfn.SWITCH(H2,"Critical",4,"High",3,"Medium",2,"Low",1,0))*(_xlfn.SWITCH(I2,"High",3,"Highly Probable",3,"Medium",2,"Probable",2,"Low",1,"Less Likely",1,0)),""))} | Q21: =IF(P2="","",IF(P2>=9,"CRITICAL",IF(P2>=6,"HIGH",IF(P2>=3,"MEDIUM","LOW")))) | R21: =IF(AND(D2<>"",OR(F2="Active",F2="Escalated to Issue")),TODAY()-D2,"")
A22: R-023 | P22: {=IF(OR(B2="",F2="Inactive"),"",IF(AND(H2<>"",I2<>""),(_xlfn.SWITCH(H2,"Critical",4,"High",3,"Medium",2,"Low",1,0))*(_xlfn.SWITCH(I2,"High",3,"Highly Probable",3,"Medium",2,"Probable",2,"Low",1,"Less Likely",1,0)),""))} | Q22: =IF(P2="","",IF(P2>=9,"CRITICAL",IF(P2>=6,"HIGH",IF(P2>=3,"MEDIUM","LOW")))) | R22: =IF(AND(D2<>"",OR(F2="Active",F2="Escalated to Issue")),TODAY()-D2,"")
